Workbook

Sheet Summary
A1: CapitalFacile: 24-month projection summary (CAD)
A2: Revenue = 6% client fee + your 50% of AFN's commission. Profit is before income tax and before paying yourself. Change inputs on the Assumptions tab.
A4: Metric | B4: Conservative | C4: Base | D4: Strong
A5: YEAR 1
A6: Funded deals (new + renewals) | B6: =Conservative!AA7+Conservative!AA9 -> 11.025 | C6: =Base!AA7+Base!AA9 -> 68.221154 | D6: =Strong!AA7+Strong!AA9 -> 240.975
A7: Funded volume | B7: =Conservative!AA11 -> 385875 | C7: =Base!AA11 -> 3411057.7 | D7: =Strong!AA11 -> 15663375
A8: Client success fees | B8: =Conservative!AA13 -> 18340.875 | C8: =Base!AA13 -> 168784.62 | D8: =Strong!AA13 -> 911608.43
A9: Your share of AFN commission | B9: =Conservative!AA14 -> 10650.15 | C9: =Base!AA14 -> 129620.19 | D9: =Strong!AA14 -> 759673.69
A10: Total revenue | B10: =Conservative!AA15 -> 28991.025 | C10: =Base!AA15 -> 298404.81 | D10: =Strong!AA15 -> 1671282.1
A11: Ad spend | B11: =Conservative!AA17 -> 68500 | C11: =Base!AA17 -> 159000 | D11: =Strong!AA17 -> 261000
A12: Net profit before tax | B12: =Conservative!AA21 -> -58611.475 | C12: =Base!AA21 -> 115264.9 | D12: =Strong!AA21 -> 1364594.4
A13: YEAR 2
A14: Funded deals (new + renewals) | B14: =Conservative!AB7+Conservative!AB9 -> 17.71875 | C14: =Base!AB7+Base!AB9 -> 148.61538 | D14: =Strong!AB7+Strong!AB9 -> 522.45278
A15: Funded volume | B15: =Conservative!AB11 -> 620156.25 | C15: =Base!AB11 -> 7430769.2 | D15: =Strong!AB11 -> 33959431
A16: Total revenue | B16: =Conservative!AB15 -> 42820.312 | C16: =Base!AB15 -> 598176.92 | D16: =Strong!AB15 -> 3623471.2
A17: Ad spend | B17: =Conservative!AB17 -> 96000 | C17: =Base!AB17 -> 297500 | D17: =Strong!AB17 -> 478000
A18: Net profit before tax | B18: =Conservative!AB21 -> -72951.562 | C18: =Base!AB21 -> 269301.54 | D18: =Strong!AB21 -> 3074450.5
A19: RUN RATE AT MONTH 24
A20: Monthly revenue | B20: =Conservative!Z15 -> 3591 | C20: =Base!Z15 -> 51201.923 | D20: =Strong!Z15 -> 312868.11
A21: Monthly net profit | B21: =Conservative!Z21 -> -6059 | C21: =Base!Z21 -> 23533.654 | D21: =Strong!Z21 -> 266808.11
A22: Leads to call per business day | B22: =Conservative!Z26 -> 1.843318 | C22: =Base!Z26 -> 8.8621056 | D22: =Strong!Z26 -> 20.481311
A23: UNIT ECONOMICS
A24: Revenue per new funded deal | B24: =Assumptions!C23 -> 2751 | C24: =Assumptions!D23 -> 4660 | D24: =Assumptions!E23 -> 6935.5
A25: Ad spend per new funded deal (CAC) | B25: =Assumptions!C25 -> 6666.6667 | C25: =Assumptions!D25 -> 2600 | D25: =Assumptions!E25 -> 1285.7143
A26: Profit per new funded deal | B26: =Assumptions!C26 -> -4015.6667 | C26: =Assumptions!D26 -> 1970 | D26: =Assumptions!E26 -> 5559.7857
A27: Max cost per lead to break even | B27: =Assumptions!C27 -> 79.53 | C27: =Assumptions!D27 -> 228.5 | D27: =Assumptions!E27 -> 479.185
A28: Funded deals/month needed for $1M profit/yr | B28: =Assumptions!C29 -> Not reachable | C28: =Assumptions!D29 -> 43.062606 | D28: =Assumptions!E29 -> 15.348313
A30: How to read this:
A31: - The biggest unknown is what AFN earns per deal (Assumptions row 'Commission the lender pays AFN'). Ask Amir and update it.
A32: - The model is most sensitive to cost per lead and lead-to-funded conversion. After 30 days of ads, replace both with your real numbers.
A33: - If 'Profit per new funded deal' is negative, cut ad spend and fix conversion first: scaling a losing funnel loses more money.
A34: - Renewals are where the margin is: no ad spend, AFN still pays your 50%. Stay in touch with every funded client.
A35: - Cash timing: client fee is collected ~2 business days after funding; AFN pays within 7 business days but may hold up to 45 days (Schedule A).
A36: - Not included: income tax, your salary, a second closer's pay, legal fees, any reduction of the 50% split by AFN.

Sheet Goal_30_per_month
A1: Goal: 30 funded deals a month (1 per business day)
A2: Works backward from the deal target. Green cells pull the Base case from the Assumptions tab; blue cells are inputs you can change here.
A4: Inputs
A5: Funded deals per month (new clients) | B5: 30 | C5: Your goal.
A6: Average funded amount | B6: =Assumptions!D5 -> 50000 | C6: Base case.
A7: Cost per lead | B7: =Assumptions!D6 -> 130 | C7: Base case. Usually rises as you spend more on the same keywords.
A8: Lead to funded conversion | B8: =Assumptions!D7 -> 0.05 | C8: Base case.
A9: Business days per month | B9: 21.7
A10: New leads one person can call well per day | B10: 15 | C10: Assumption: first call ~15 min + follow-ups, document chasing and closing on open files.
A12: What it takes each month
A13: Leads needed | B13: =B5/B8 -> 600
A14: Leads to call per business day | B14: =B13/B9 -> 27.64977
A15: People needed on the phones (incl. you) | B15: =ROUNDUP(B14/B10,0) -> 2 | C15: Hire a qualifier who calls within 5 min and hands you the good files.
A16: Google Ads budget | B16: =B13*B7 -> 78000 | C16: Paid before the money comes in.
A17: Funded volume | B17: =B5*B6 -> 1500000
A18: Client success fees (collected) | B18: =B17*Assumptions!D11*Assumptions!D12 -> 82800 | C18: 6% x collection rate.
A19: Your 50% of AFN commission | B19: =B17*Assumptions!D13*Assumptions!D14*(1-Assumptions!D15) -> 57000 | C19: Depends on what the lender pays AFN: ask Amir.
A20: Total revenue | B20: =B18+B19 -> 139800
A21: Variable costs | B21: =B5*Assumptions!D20 -> 2700
A22: Fixed costs | B22: =Assumptions!D19 -> 1500
A23: Net profit per month (before tax, team pay) | B23: =B20-B16-B21-B22 -> 57600 | C23: Pay a qualifier out of this.
A24: Net profit per year | B24: =B23*12 -> 691200
A26: Once renewals kick in (steady state, ~6 months in)
A27: Renewal deals per month | B27: =B5*Assumptions!D16 -> 10.5 | C27: Base renewal rate. No ad spend.
A28: Renewal revenue | B28: =B27*B6*(Assumptions!D13*Assumptions!D14*(1-Assumptions!D15)+Assumptions!D18*Assumptions!D11*Assumptions!D12) -> 19950 | C28: AFN pays your 50% on renewals.
A29: Net profit per month with renewals | B29: =B23+B28-B27*Assumptions!D20 -> 76605
A30: Net profit per year with renewals | B30: =B29*12 -> 919260
A33: Monthly Google Ads budget needed for the target
A34: Conversion ↓ / Cost per lead → | B34: 90 | C34: 130 | D34: 200
A35: 0.03 | B35: =$B$5/$A35*B$34 -> 90000 | C35: =$B$5/$A35*C$34 -> 130000 | D35: =$B$5/$A35*D$34 -> 200000
A36: 0.05 | B36: =$B$5/$A36*B$34 -> 54000 | C36: =$B$5/$A36*C$34 -> 78000 | D36: =$B$5/$A36*D$34 -> 120000
A37: 0.07 | B37: =$B$5/$A37*B$34 -> 38571.429 | C37: =$B$5/$A37*C$34 -> 55714.286 | D37: =$B$5/$A37*D$34 -> 85714.286
A38: 0.1 | B38: =$B$5/$A38*B$34 -> 27000 | C38: =$B$5/$A38*C$34 -> 39000 | D38: =$B$5/$A38*D$34 -> 60000
A40: Monthly net profit at the target (before renewals)
A41: Conversion ↓ / Cost per lead → | B41: 90 | C41: 130 | D41: 200
A42: 0.03 | B42: =$B$20-$B$21-$B$22-$B$5/$A42*B$41 -> 45600 | C42: =$B$20-$B$21-$B$22-$B$5/$A42*C$41 -> 5600 | D42: =$B$20-$B$21-$B$22-$B$5/$A42*D$41 -> -64400
A43: 0.05 | B43: =$B$20-$B$21-$B$22-$B$5/$A43*B$41 -> 81600 | C43: =$B$20-$B$21-$B$22-$B$5/$A43*C$41 -> 57600 | D43: =$B$20-$B$21-$B$22-$B$5/$A43*D$41 -> 15600
A44: 0.07 | B44: =$B$20-$B$21-$B$22-$B$5/$A44*B$41 -> 97028.571 | C44: =$B$20-$B$21-$B$22-$B$5/$A44*C$41 -> 79885.714 | D44: =$B$20-$B$21-$B$22-$B$5/$A44*D$41 -> 49885.714
A45: 0.1 | B45: =$B$20-$B$21-$B$22-$B$5/$A45*B$41 -> 108600 | C45: =$B$20-$B$21-$B$22-$B$5/$A45*C$41 -> 96600 | D45: =$B$20-$B$21-$B$22-$B$5/$A45*D$41 -> 75600
A47: Cash: you pay for ads up front. The client fee arrives ~2 business days after funding, but AFN can hold its commission up to 45 days (Schedule A).
...

Sheet Assumptions
A1: CapitalFacile: 24-month projection assumptions
A2: Blue = input you can change. Yellow = key assumption to confirm. All amounts in CAD. Model starts the month paid ads go live.
A4: Assumption | B4: Unit | C4: Conservative | D4: Base | E4: Strong | F4: Source / note
A5: Average funded amount per deal | B5: $ | C5: 35000 | D5: 50000 | E5: 65000 | F5: Estimate for Quebec SMB revenue-based advances. Confirm with AFN's average funded size.
A6: Cost per lead (Google Ads) | B6: $ | C6: 200 | D6: 130 | E6: 90 | F6: Estimate: ~$8-15 CPC on French business-financing keywords x 6-10% landing-page conversion. Replace with real data after 30 days of ads.
A7: Lead to funded deal conversion | B7: % | C7: 0.03 | D7: 0.05 | E7: 0.07 | F7: Estimate for paid search leads to a revenue-based funding broker. Your 5-minute callback is the main lever here.
A8: Ad spend, month 1 | B8: $ | C8: 3000 | D8: 5000 | E8: 8000 | F8: Your choice.
A9: Ad spend increase per month | B9: $ | C9: 500 | D9: 1500 | E9: 2500 | F9: Your choice.
A10: Max ad spend per month | B10: $ | C10: 8000 | D10: 25000 | E10: 40000 | F10: Cap so leads stay callable by one person (see 'Leads per business day' on each projection tab). Strong case needs a second closer.
A11: Client success fee | B11: % | C11: 0.06 | D11: 0.06 | E11: 0.06 | F11: Your mandate: 6% of gross amount funded. Requires AFN's written OK (Schedule A).
A12: Share of client fees actually collected | B12: % | C12: 0.85 | D12: 0.92 | E12: 0.97 | F12: Estimate. Some clients will dispute or block the PAD. Signed mandate + PAD before submitting the file protects this.
A13: Commission the lender pays AFN | B13: % of funded | C13: 0.06 | D13: 0.08 | E13: 0.1 | F13: UNKNOWN: not stated in the agreement. Ask Amir what AFN typically receives per deal. Biggest uncertainty in this model.
A14: Your share of AFN's commission | B14: % | C14: 0.5 | D14: 0.5 | E14: 0.5 | F14: Schedule A of the AFN Partner Agreement (signed 2026-09-24): 50%, initial and renewals; 'subject to reconsideration'.
A15: Deals defaulting within 45 days | B15: % | C15: 0.08 | D15: 0.05 | E15: 0.03 | F15: Schedule A: no AFN commission (and clawback) if client defaults within 45 days. Rate is an estimate.
A16: Funded clients who renew | B16: % | C16: 0.25 | D16: 0.35 | E16: 0.45 | F16: Estimate. Renewals cost no ad spend; AFN pays your 50% on renewals (Schedule A) if you send 2+ new merchants per year.
... A20: Variable cost per funded deal | B20: $ | C20: 100 | D20: 90 | E20: 90 | F20: PAD processing, e-signature, bank-data API.
A22: Unit economics (calculated)
A23: Revenue per new funded deal | B23: $ | C23: =C5*(C11*C12+C13*C14*(1-C15)) -> 2751 | D23: =D5*(D11*D12+D13*D14*(1-D15)) -> 4660 | E23: =E5*(E11*E12+E13*E14*(1-E15)) -> 6935.5 | F23: Client fee collected + your share of AFN commission, net of 45-day defaults.
A24: Revenue as % of amount funded | B24: % | C24: =IFERROR(C23/C5,0) -> 0.0786 | D24: =IFERROR(D23/D5,0) -> 0.0932 | E24: =IFERROR(E23/E5,0) -> 0.1067
A25: Ad spend per new funded deal (CAC) | B25: $ | C25: =IFERROR(C6/C7,0) -> 6666.6667 | D25: =IFERROR(D6/D7,0) -> 2600 | E25: =IFERROR(E6/E7,0) -> 1285.7143 | F25: Cost per lead / conversion.
A26: Profit per new funded deal (before fixed costs) | B26: $ | C26: =C23-C25-C20 -> -4015.6667 | D26: =D23-D25-D20 -> 1970 | E26: =E23-E25-E20 -> 5559.7857 | F26: If this is negative, more ad spend = bigger losses.
A27: Max cost per lead to break even on a deal | B27: $ | C27: =(C23-C20)*C7 -> 79.53 | D27: =(D23-D20)*D7 -> 228.5 | E27: =(E23-E20)*E7 -> 479.185 | F27: Track your real cost per lead against this number from week 1.
A28: Annual funded volume needed for $1M profit/yr (new deals only) | B28: $ | C28: =IF(C26>0,(1000000+12*C19)/(C26/C5),"Not reachable") -> Not reachable | D28: =IF(D26>0,(1000000+12*D19)/(D26/D5),"Not reachable") -> 25837563 | E28: =IF(E26>0,(1000000+12*E19)/(E26/E5),"Not reachable") -> 11971684 | F28: Steady state, ignores renewals (which make it easier).
A29: Funded deals per month needed for $1M profit/yr | B29: deals | C29: =IF(ISNUMBER(C28),C28/C5/12,"Not reachable") -> Not reachable | D29: =IF(ISNUMBER(D28),D28/D5/12,"Not reachable") -> 43.062606 | E29: =IF(ISNUMBER(E28),E28/E5/12,"Not reachable") -> 15.348313

Sheet Conservative
A1: Conservative scenario: monthly projection (CAD)
A2: All inputs come from column C of the Assumptions tab (green = linked). Profit is before income tax and before paying yourself.
A4: Month | C4: 1 | D4: =C4+1 -> 2 | E4: =D4+1 -> 3 | F4: =E4+1 -> 4 | G4: =F4+1 -> 5 | H4: =G4+1 -> 6 | I4: =H4+1 -> 7 | J4: =I4+1 -> 8 | K4: =J4+1 -> 9 | ... Z4: =Y4+1 -> 24 | AA4: Year 1 | AB4: Year 2 | AC4: 24 months
A5: Ad spend | C5: =MIN(Assumptions!$C$8+(C$4-1)*Assumptions!$C$9,Assumptions!$C$10) -> 3000 | D5: =MIN(Assumptions!$C$8+(D$4-1)*Assumptions!$C$9,Assumptions!$C$10) -> 3500 | E5: =MIN(Assumptions!$C$8+(E$4-1)*Assumptions!$C$9,Assumptions!$C$10) -> 4000 | F5: =MIN(Assumptions!$C$8+(F$4-1)*Assumptions!$C$9,Assumptions!$C$10) -> 4500 | G5: =MIN(Assumptions!$C$8+(G$4-1)*Assumptions!$C$9,Assumptions!$C$10) -> 5000 | H5: =MIN(Assumptions!$C$8+(H$4-1)*Assumptions!$C$9,Assumptions!$C$10) -> 5500 | I5: =MIN(Assumptions!$C$8+(I$4-1)*Assumptions!$C$9,Assumptions!$C$10) -> 6000 | J5: =MIN(Assumptions!$C$8+(J$4-1)*Assumptions!$C$9,Assumptions!$C$10) -> 6500 | ... Z5: =MIN(Assumptions!$C$8+(Z$4-1)*Assumptions!$C$9,Assumptions!$C$10) -> 8000 | AA5: =SUM(C5:N5) -> 68500 | AB5: =SUM(O5:Z5) -> 96000 | AC5: =AA5+AB5 -> 164500
A6: Leads | C6: =C5/Assumptions!$C$6 -> 15 | D6: =D5/Assumptions!$C$6 -> 17.5 | E6: =E5/Assumptions!$C$6 -> 20 | F6: =F5/Assumptions!$C$6 -> 22.5 | G6: =G5/Assumptions!$C$6 -> 25 | H6: =H5/Assumptions!$C$6 -> 27.5 | I6: =I5/Assumptions!$C$6 -> 30 | J6: =J5/Assumptions!$C$6 -> 32.5 | ... Z6: =Z5/Assumptions!$C$6 -> 40 | AA6: =SUM(C6:N6) -> 342.5 | AB6: =SUM(O6:Z6) -> 480 | AC6: =AA6+AB6 -> 822.5
A7: New funded deals | C7: =C6*Assumptions!$C$7 -> 0.45 | D7: =D6*Assumptions!$C$7 -> 0.525 | E7: =E6*Assumptions!$C$7 -> 0.6 | F7: =F6*Assumptions!$C$7 -> 0.675 | G7: =G6*Assumptions!$C$7 -> 0.75 | H7: =H6*Assumptions!$C$7 -> 0.825 | I7: =I6*Assumptions!$C$7 -> 0.9 | J7: =J6*Assumptions!$C$7 -> 0.975 | ... Z7: =Z6*Assumptions!$C$7 -> 1.2 | AA7: =SUM(C7:N7) -> 10.275 | AB7: =SUM(O7:Z7) -> 14.4 | AC7: =AA7+AB7 -> 24.675
A8: New funded volume | C8: =C7*Assumptions!$C$5 -> 15750 | D8: =D7*Assumptions!$C$5 -> 18375 | E8: =E7*Assumptions!$C$5 -> 21000 | F8: =F7*Assumptions!$C$5 -> 23625 | G8: =G7*Assumptions!$C$5 -> 26250 | H8: =H7*Assumptions!$C$5 -> 28875 | I8: =I7*Assumptions!$C$5 -> 31500 | J8: =J7*Assumptions!$C$5 -> 34125 | ... Z8: =Z7*Assumptions!$C$5 -> 42000 | AA8: =SUM(C8:N8) -> 359625 | AB8: =SUM(O8:Z8) -> 504000 | AC8: =AA8+AB8 -> 863625
A9: Renewal deals | C9: =IF(C$4>Assumptions!$C$17,INDEX($C$7:$Z$7,C$4-Assumptions!$C$17)*Assumptions!$C$16,0) -> 0 | D9: =IF(D$4>Assumptions!$C$17,INDEX($C$7:$Z$7,D$4-Assumptions!$C$17)*Assumptions!$C$16,0) -> 0 | E9: =IF(E$4>Assumptions!$C$17,INDEX($C$7:$Z$7,E$4-Assumptions!$C$17)*Assumptions!$C$16,0) -> 0 | F9: =IF(F$4>Assumptions!$C$17,INDEX($C$7:$Z$7,F$4-Assumptions!$C$17)*Assumptions!$C$16,0) -> 0 | G9: =IF(G$4>Assumptions!$C$17,INDEX($C$7:$Z$7,G$4-Assumptions!$C$17)*Assumptions!$C$16,0) -> 0 | H9: =IF(H$4>Assumptions!$C$17,INDEX($C$7:$Z$7,H$4-Assumptions!$C$17)*Assumptions!$C$16,0) -> 0 | I9: =IF(I$4>Assumptions!$C$17,INDEX($C$7:$Z$7,I$4-Assumptions!$C$17)*Assumptions!$C$16,0) -> 0 | J9: =IF(J$4>Assumptions!$C$17,INDEX($C$7:$Z$7,J$4-Assumptions!$C$17)*Assumptions!$C$16,0) -> 0.1125 | ... Z9: =IF(Z$4>Assumptions!$C$17,INDEX($C$7:$Z$7,Z$4-Assumptions!$C$17)*Assumptions!$C$16,0) -> 0.3 | AA9: =SUM(C9:N9) -> 0.75 | AB9: =SUM(O9:Z9) -> 3.31875 | AC9: =AA9+AB9 -> 4.06875
A10: Renewal volume | C10: =C9*Assumptions!$C$5 -> 0 | D10: =D9*Assumptions!$C$5 -> 0 | E10: =E9*Assumptions!$C$5 -> 0 | F10: =F9*Assumptions!$C$5 -> 0 | G10: =G9*Assumptions!$C$5 -> 0 | H10: =H9*Assumptions!$C$5 -> 0 | I10: =I9*Assumptions!$C$5 -> 0 | J10: =J9*Assumptions!$C$5 -> 3937.5 | ... Z10: =Z9*Assumptions!$C$5 -> 10500 | AA10: =SUM(C10:N10) -> 26250 | AB10: =SUM(O10:Z10) -> 116156.25 | AC10: =AA10+AB10 -> 142406.25
A11: Total funded volume | C11: =C8+C10 -> 15750 | D11: =D8+D10 -> 18375 | E11: =E8+E10 -> 21000 | F11: =F8+F10 -> 23625 | G11: =G8+G10 -> 26250 | H11: =H8+H10 -> 28875 | I11: =I8+I10 -> 31500 | J11: =J8+J10 -> 38062.5 | ... Z11: =Z8+Z10 -> 52500 | AA11: =SUM(C11:N11) -> 385875 | AB11: =SUM(O11:Z11) -> 620156.25 | AC11: =AA11+AB11 -> 1006031.2
A12: Revenue
A13: Client success fees (collected) | C13: =(C8+C10*Assumptions!$C$18)*Assumptions!$C$11*Assumptions!$C$12 -> 803.25 | D13: =(D8+D10*Assumptions!$C$18)*Assumptions!$C$11*Assumptions!$C$12 -> 937.125 | E13: =(E8+E10*Assumptions!$C$18)*Assumptions!$C$11*Assumptions!$C$12 -> 1071 | F13: =(F8+F10*Assumptions!$C$18)*Assumptions!$C$11*Assumptions!$C$12 -> 1204.875 | G13: =(G8+G10*Assumptions!$C$18)*Assumptions!$C$11*Assumptions!$C$12 -> 1338.75 | H13: =(H8+H10*Assumptions!$C$18)*Assumptions!$C$11*Assumptions!$C$12 -> 1472.625 | I13: =(I8+I10*Assumptions!$C$18)*Assumptions!$C$11*Assumptions!$C$12 -> 1606.5 | J13: =(J8+J10*Assumptions!$C$18)*Assumptions!$C$11*Assumptions!$C$12 -> 1740.375 | ... Z13: =(Z8+Z10*Assumptions!$C$18)*Assumptions!$C$11*Assumptions!$C$12 -> 2142 | AA13: =SUM(C13:N13) -> 18340.875 | AB13: =SUM(O13:Z13) -> 25704 | AC13: =AA13+AB13 -> 44044.875
A14: Your 50% of AFN commission | C14: =C11*Assumptions!$C$13*Assumptions!$C$14*(1-Assumptions!$C$15) -> 434.7 | D14: =D11*Assumptions!$C$13*Assumptions!$C$14*(1-Assumptions!$C$15) -> 507.15 | E14: =E11*Assumptions!$C$13*Assumptions!$C$14*(1-Assumptions!$C$15) -> 579.6 | F14: =F11*Assumptions!$C$13*Assumptions!$C$14*(1-Assumptions!$C$15) -> 652.05 | G14: =G11*Assumptions!$C$13*Assumptions!$C$14*(1-Assumptions!$C$15) -> 724.5 | H14: =H11*Assumptions!$C$13*Assumptions!$C$14*(1-Assumptions!$C$15) -> 796.95 | I14: =I11*Assumptions!$C$13*Assumptions!$C$14*(1-Assumptions!$C$15) -> 869.4 | J14: =J11*Assumptions!$C$13*Assumptions!$C$14*(1-Assumptions!$C$15) -> 1050.525 | ... Z14: =Z11*Assumptions!$C$13*Assumptions!$C$14*(1-Assumptions!$C$15) -> 1449 | AA14: =SUM(C14:N14) -> 10650.15 | AB14: =SUM(O14:Z14) -> 17116.312 | AC14: =AA14+AB14 -> 27766.463
A15: Total revenue | C15: =C13+C14 -> 1237.95 | D15: =D13+D14 -> 1444.275 | E15: =E13+E14 -> 1650.6 | F15: =F13+F14 -> 1856.925 | G15: =G13+G14 -> 2063.25 | H15: =H13+H14 -> 2269.575 | I15: =I13+I14 -> 2475.9 | J15: =J13+J14 -> 2790.9 | ... Z15: =Z13+Z14 -> 3591 | AA15: =SUM(C15:N15) -> 28991.025 | AB15: =SUM(O15:Z15) -> 42820.312 | AC15: =AA15+AB15 -> 71811.337
A16: Costs
A17: Ad spend | C17: =C5 -> 3000 | D17: =D5 -> 3500 | E17: =E5 -> 4000 | F17: =F5 -> 4500 | G17: =G5 -> 5000 | H17: =H5 -> 5500 | I17: =I5 -> 6000 | J17: =J5 -> 6500 | ... Z17: =Z5 -> 8000 | AA17: =SUM(C17:N17) -> 68500 | AB17: =SUM(O17:Z17) -> 96000 | AC17: =AA17+AB17 -> 164500
A18: Fixed costs | C18: =Assumptions!$C$19 -> 1500 | D18: =Assumptions!$C$19 -> 1500 | E18: =Assumptions!$C$19 -> 1500 | F18: =Assumptions!$C$19 -> 1500 | G18: =Assumptions!$C$19 -> 1500 | H18: =Assumptions!$C$19 -> 1500 | I18: =Assumptions!$C$19 -> 1500 | J18: =Assumptions!$C$19 -> 1500 | ... Z18: =Assumptions!$C$19 -> 1500 | AA18: =SUM(C18:N18) -> 18000 | AB18: =SUM(O18:Z18) -> 18000 | AC18: =AA18+AB18 -> 36000
A19: Variable costs | C19: =(C7+C9)*Assumptions!$C$20 -> 45 | D19: =(D7+D9)*Assumptions!$C$20 -> 52.5 | E19: =(E7+E9)*Assumptions!$C$20 -> 60 | F19: =(F7+F9)*Assumptions!$C$20 -> 67.5 | G19: =(G7+G9)*Assumptions!$C$20 -> 75 | H19: =(H7+H9)*Assumptions!$C$20 -> 82.5 | I19: =(I7+I9)*Assumptions!$C$20 -> 90 | J19: =(J7+J9)*Assumptions!$C$20 -> 108.75 | ... Z19: =(Z7+Z9)*Assumptions!$C$20 -> 150 | AA19: =SUM(C19:N19) -> 1102.5 | AB19: =SUM(O19:Z19) -> 1771.875 | AC19: =AA19+AB19 -> 2874.375
A20: Total costs | C20: =SUM(C17:C19) -> 4545 | D20: =SUM(D17:D19) -> 5052.5 | E20: =SUM(E17:E19) -> 5560 | F20: =SUM(F17:F19) -> 6067.5 | G20: =SUM(G17:G19) -> 6575 | H20: =SUM(H17:H19) -> 7082.5 | I20: =SUM(I17:I19) -> 7590 | J20: =SUM(J17:J19) -> 8108.75 | ... Z20: =SUM(Z17:Z19) -> 9650 | AA20: =SUM(C20:N20) -> 87602.5 | AB20: =SUM(O20:Z20) -> 115771.88 | AC20: =AA20+AB20 -> 203374.38
A21: Net profit before tax | C21: =C15-C20 -> -3307.05 | D21: =D15-D20 -> -3608.225 | E21: =E15-E20 -> -3909.4 | F21: =F15-F20 -> -4210.575 | G21: =G15-G20 -> -4511.75 | H21: =H15-H20 -> -4812.925 | I21: =I15-I20 -> -5114.1 | J21: =J15-J20 -> -5317.85 | ... Z21: =Z15-Z20 -> -6059 | AA21: =SUM(C21:N21) -> -58611.475 | AB21: =SUM(O21:Z21) -> -72951.562 | AC21: =AA21+AB21 -> -131563.04
A22: Cumulative net profit | C22: =C21 -> -3307.05 | D22: =C22+D21 -> -6915.275 | E22: =D22+E21 -> -10824.675 | F22: =E22+F21 -> -15035.25 | G22: =F22+G21 -> -19547 | H22: =G22+H21 -> -24359.925 | I22: =H22+I21 -> -29474.025 | J22: =I22+J21 -> -34791.875 | K22: =J22+K21 -> -40394.662 | ... Z22: =Y22+Z21 -> -131563.04 | AA22: =N22 -> -58611.475 | AB22: =Z22 -> -131563.04 | AC22: =Z22 -> -131563.04
A23: Metrics
A24: Ad spend per new funded deal | C24: =IFERROR(C5/C7,0) -> 6666.6667 | D24: =IFERROR(D5/D7,0) -> 6666.6667 | E24: =IFERROR(E5/E7,0) -> 6666.6667 | F24: =IFERROR(F5/F7,0) -> 6666.6667 | G24: =IFERROR(G5/G7,0) -> 6666.6667 | H24: =IFERROR(H5/H7,0) -> 6666.6667 | I24: =IFERROR(I5/I7,0) -> 6666.6667 | J24: =IFERROR(J5/J7,0) -> 6666.6667 | ... AC24: =IFERROR(AC5/AC7,0) -> 6666.6667
A25: Revenue per funded deal | C25: =IFERROR(C15/(C7+C9),0) -> 2751 | D25: =IFERROR(D15/(D7+D9),0) -> 2751 | E25: =IFERROR(E15/(E7+E9),0) -> 2751 | F25: =IFERROR(F15/(F7+F9),0) -> 2751 | G25: =IFERROR(G15/(G7+G9),0) -> 2751 | H25: =IFERROR(H15/(H7+H9),0) -> 2751 | I25: =IFERROR(I15/(I7+I9),0) -> 2751 | J25: =IFERROR(J15/(J7+J9),0) -> 2566.3448 | ... AC25: =IFERROR(AC15/(AC7+AC9),0) -> 2498.3288
A26: Leads to call per business day | C26: =C6/21.7 -> 0.69124424 | D26: =D6/21.7 -> 0.80645161 | E26: =E6/21.7 -> 0.92165899 | F26: =F6/21.7 -> 1.0368664 | G26: =G6/21.7 -> 1.1520737 | H26: =H6/21.7 -> 1.2672811 | I26: =I6/21.7 -> 1.3824885 | J26: =J6/21.7 -> 1.4976959 | ... Z26: =Z6/21.7 -> 1.843318

Sheet Base
A1: Base scenario: monthly projection (CAD)
A2: All inputs come from column D of the Assumptions tab (green = linked). Profit is before income tax and before paying yourself.
A4: Month | C4: 1 | D4: =C4+1 -> 2 | E4: =D4+1 -> 3 | F4: =E4+1 -> 4 | G4: =F4+1 -> 5 | H4: =G4+1 -> 6 | I4: =H4+1 -> 7 | J4: =I4+1 -> 8 | K4: =J4+1 -> 9 | ... Z4: =Y4+1 -> 24 | AA4: Year 1 | AB4: Year 2 | AC4: 24 months
A5: Ad spend | C5: =MIN(Assumptions!$D$8+(C$4-1)*Assumptions!$D$9,Assumptions!$D$10) -> 5000 | D5: =MIN(Assumptions!$D$8+(D$4-1)*Assumptions!$D$9,Assumptions!$D$10) -> 6500 | E5: =MIN(Assumptions!$D$8+(E$4-1)*Assumptions!$D$9,Assumptions!$D$10) -> 8000 | F5: =MIN(Assumptions!$D$8+(F$4-1)*Assumptions!$D$9,Assumptions!$D$10) -> 9500 | G5: =MIN(Assumptions!$D$8+(G$4-1)*Assumptions!$D$9,Assumptions!$D$10) -> 11000 | H5: =MIN(Assumptions!$D$8+(H$4-1)*Assumptions!$D$9,Assumptions!$D$10) -> 12500 | I5: =MIN(Assumptions!$D$8+(I$4-1)*Assumptions!$D$9,Assumptions!$D$10) -> 14000 | J5: =MIN(Assumptions!$D$8+(J$4-1)*Assumptions!$D$9,Assumptions!$D$10) -> 15500 | ... Z5: =MIN(Assumptions!$D$8+(Z$4-1)*Assumptions!$D$9,Assumptions!$D$10) -> 25000 | AA5: =SUM(C5:N5) -> 159000 | AB5: =SUM(O5:Z5) -> 297500 | AC5: =AA5+AB5 -> 456500
A6: Leads | C6: =C5/Assumptions!$D$6 -> 38.461538 | D6: =D5/Assumptions!$D$6 -> 50 | E6: =E5/Assumptions!$D$6 -> 61.538462 | F6: =F5/Assumptions!$D$6 -> 73.076923 | G6: =G5/Assumptions!$D$6 -> 84.615385 | H6: =H5/Assumptions!$D$6 -> 96.153846 | I6: =I5/Assumptions!$D$6 -> 107.69231 | J6: =J5/Assumptions!$D$6 -> 119.23077 | ... Z6: =Z5/Assumptions!$D$6 -> 192.30769 | AA6: =SUM(C6:N6) -> 1223.0769 | AB6: =SUM(O6:Z6) -> 2288.4615 | AC6: =AA6+AB6 -> 3511.5385
A7: New funded deals | C7: =C6*Assumptions!$D$7 -> 1.9230769 | D7: =D6*Assumptions!$D$7 -> 2.5 | E7: =E6*Assumptions!$D$7 -> 3.0769231 | F7: =F6*Assumptions!$D$7 -> 3.6538462 | G7: =G6*Assumptions!$D$7 -> 4.2307692 | H7: =H6*Assumptions!$D$7 -> 4.8076923 | I7: =I6*Assumptions!$D$7 -> 5.3846154 | J7: =J6*Assumptions!$D$7 -> 5.9615385 | ... Z7: =Z6*Assumptions!$D$7 -> 9.6153846 | AA7: =SUM(C7:N7) -> 61.153846 | AB7: =SUM(O7:Z7) -> 114.42308 | AC7: =AA7+AB7 -> 175.57692
A8: New funded volume | C8: =C7*Assumptions!$D$5 -> 96153.846 | D8: =D7*Assumptions!$D$5 -> 125000 | E8: =E7*Assumptions!$D$5 -> 153846.15 | F8: =F7*Assumptions!$D$5 -> 182692.31 | G8: =G7*Assumptions!$D$5 -> 211538.46 | H8: =H7*Assumptions!$D$5 -> 240384.62 | I8: =I7*Assumptions!$D$5 -> 269230.77 | J8: =J7*Assumptions!$D$5 -> 298076.92 | ... Z8: =Z7*Assumptions!$D$5 -> 480769.23 | AA8: =SUM(C8:N8) -> 3057692.3 | AB8: =SUM(O8:Z8) -> 5721153.8 | AC8: =AA8+AB8 -> 8778846.2
A9: Renewal deals | C9: =IF(C$4>Assumptions!$D$17,INDEX($C$7:$Z$7,C$4-Assumptions!$D$17)*Assumptions!$D$16,0) -> 0 | D9: =IF(D$4>Assumptions!$D$17,INDEX($C$7:$Z$7,D$4-Assumptions!$D$17)*Assumptions!$D$16,0) -> 0 | E9: =IF(E$4>Assumptions!$D$17,INDEX($C$7:$Z$7,E$4-Assumptions!$D$17)*Assumptions!$D$16,0) -> 0 | F9: =IF(F$4>Assumptions!$D$17,INDEX($C$7:$Z$7,F$4-Assumptions!$D$17)*Assumptions!$D$16,0) -> 0 | G9: =IF(G$4>Assumptions!$D$17,INDEX($C$7:$Z$7,G$4-Assumptions!$D$17)*Assumptions!$D$16,0) -> 0 | H9: =IF(H$4>Assumptions!$D$17,INDEX($C$7:$Z$7,H$4-Assumptions!$D$17)*Assumptions!$D$16,0) -> 0 | I9: =IF(I$4>Assumptions!$D$17,INDEX($C$7:$Z$7,I$4-Assumptions!$D$17)*Assumptions!$D$16,0) -> 0.67307692 | J9: =IF(J$4>Assumptions!$D$17,INDEX($C$7:$Z$7,J$4-Assumptions!$D$17)*Assumptions!$D$16,0) -> 0.875 | ... Z9: =IF(Z$4>Assumptions!$D$17,INDEX($C$7:$Z$7,Z$4-Assumptions!$D$17)*Assumptions!$D$16,0) -> 3.3653846 | AA9: =SUM(C9:N9) -> 7.0673077 | AB9: =SUM(O9:Z9) -> 34.192308 | AC9: =AA9+AB9 -> 41.259615
A10: Renewal volume | C10: =C9*Assumptions!$D$5 -> 0 | D10: =D9*Assumptions!$D$5 -> 0 | E10: =E9*Assumptions!$D$5 -> 0 | F10: =F9*Assumptions!$D$5 -> 0 | G10: =G9*Assumptions!$D$5 -> 0 | H10: =H9*Assumptions!$D$5 -> 0 | I10: =I9*Assumptions!$D$5 -> 33653.846 | J10: =J9*Assumptions!$D$5 -> 43750 | ... Z10: =Z9*Assumptions!$D$5 -> 168269.23 | AA10: =SUM(C10:N10) -> 353365.38 | AB10: =SUM(O10:Z10) -> 1709615.4 | AC10: =AA10+AB10 -> 2062980.8
A11: Total funded volume | C11: =C8+C10 -> 96153.846 | D11: =D8+D10 -> 125000 | E11: =E8+E10 -> 153846.15 | F11: =F8+F10 -> 182692.31 | G11: =G8+G10 -> 211538.46 | H11: =H8+H10 -> 240384.62 | I11: =I8+I10 -> 302884.62 | J11: =J8+J10 -> 341826.92 | ... Z11: =Z8+Z10 -> 649038.46 | AA11: =SUM(C11:N11) -> 3411057.7 | AB11: =SUM(O11:Z11) -> 7430769.2 | AC11: =AA11+AB11 -> 10841827
A12: Revenue
A13: Client success fees (collected) | C13: =(C8+C10*Assumptions!$D$18)*Assumptions!$D$11*Assumptions!$D$12 -> 5307.6923 | D13: =(D8+D10*Assumptions!$D$18)*Assumptions!$D$11*Assumptions!$D$12 -> 6900 | E13: =(E8+E10*Assumptions!$D$18)*Assumptions!$D$11*Assumptions!$D$12 -> 8492.3077 | F13: =(F8+F10*Assumptions!$D$18)*Assumptions!$D$11*Assumptions!$D$12 -> 10084.615 | G13: =(G8+G10*Assumptions!$D$18)*Assumptions!$D$11*Assumptions!$D$12 -> 11676.923 | H13: =(H8+H10*Assumptions!$D$18)*Assumptions!$D$11*Assumptions!$D$12 -> 13269.231 | I13: =(I8+I10*Assumptions!$D$18)*Assumptions!$D$11*Assumptions!$D$12 -> 14861.538 | J13: =(J8+J10*Assumptions!$D$18)*Assumptions!$D$11*Assumptions!$D$12 -> 16453.846 | ... Z13: =(Z8+Z10*Assumptions!$D$18)*Assumptions!$D$11*Assumptions!$D$12 -> 26538.462 | AA13: =SUM(C13:N13) -> 168784.62 | AB13: =SUM(O13:Z13) -> 315807.69 | AC13: =AA13+AB13 -> 484592.31
A14: Your 50% of AFN commission | C14: =C11*Assumptions!$D$13*Assumptions!$D$14*(1-Assumptions!$D$15) -> 3653.8462 | D14: =D11*Assumptions!$D$13*Assumptions!$D$14*(1-Assumptions!$D$15) -> 4750 | E14: =E11*Assumptions!$D$13*Assumptions!$D$14*(1-Assumptions!$D$15) -> 5846.1538 | F14: =F11*Assumptions!$D$13*Assumptions!$D$14*(1-Assumptions!$D$15) -> 6942.3077 | G14: =G11*Assumptions!$D$13*Assumptions!$D$14*(1-Assumptions!$D$15) -> 8038.4615 | H14: =H11*Assumptions!$D$13*Assumptions!$D$14*(1-Assumptions!$D$15) -> 9134.6154 | I14: =I11*Assumptions!$D$13*Assumptions!$D$14*(1-Assumptions!$D$15) -> 11509.615 | J14: =J11*Assumptions!$D$13*Assumptions!$D$14*(1-Assumptions!$D$15) -> 12989.423 | ... Z14: =Z11*Assumptions!$D$13*Assumptions!$D$14*(1-Assumptions!$D$15) -> 24663.462 | AA14: =SUM(C14:N14) -> 129620.19 | AB14: =SUM(O14:Z14) -> 282369.23 | AC14: =AA14+AB14 -> 411989.42
A15: Total revenue | C15: =C13+C14 -> 8961.5385 | D15: =D13+D14 -> 11650 | E15: =E13+E14 -> 14338.462 | F15: =F13+F14 -> 17026.923 | G15: =G13+G14 -> 19715.385 | H15: =H13+H14 -> 22403.846 | I15: =I13+I14 -> 26371.154 | J15: =J13+J14 -> 29443.269 | ... Z15: =Z13+Z14 -> 51201.923 | AA15: =SUM(C15:N15) -> 298404.81 | AB15: =SUM(O15:Z15) -> 598176.92 | AC15: =AA15+AB15 -> 896581.73
A16: Costs
A17: Ad spend | C17: =C5 -> 5000 | D17: =D5 -> 6500 | E17: =E5 -> 8000 | F17: =F5 -> 9500 | G17: =G5 -> 11000 | H17: =H5 -> 12500 | I17: =I5 -> 14000 | J17: =J5 -> 15500 | ... Z17: =Z5 -> 25000 | AA17: =SUM(C17:N17) -> 159000 | AB17: =SUM(O17:Z17) -> 297500 | AC17: =AA17+AB17 -> 456500
A18: Fixed costs | C18: =Assumptions!$D$19 -> 1500 | D18: =Assumptions!$D$19 -> 1500 | E18: =Assumptions!$D$19 -> 1500 | F18: =Assumptions!$D$19 -> 1500 | G18: =Assumptions!$D$19 -> 1500 | H18: =Assumptions!$D$19 -> 1500 | I18: =Assumptions!$D$19 -> 1500 | J18: =Assumptions!$D$19 -> 1500 | ... Z18: =Assumptions!$D$19 -> 1500 | AA18: =SUM(C18:N18) -> 18000 | AB18: =SUM(O18:Z18) -> 18000 | AC18: =AA18+AB18 -> 36000
A19: Variable costs | C19: =(C7+C9)*Assumptions!$D$20 -> 173.07692 | D19: =(D7+D9)*Assumptions!$D$20 -> 225 | E19: =(E7+E9)*Assumptions!$D$20 -> 276.92308 | F19: =(F7+F9)*Assumptions!$D$20 -> 328.84615 | G19: =(G7+G9)*Assumptions!$D$20 -> 380.76923 | H19: =(H7+H9)*Assumptions!$D$20 -> 432.69231 | I19: =(I7+I9)*Assumptions!$D$20 -> 545.19231 | J19: =(J7+J9)*Assumptions!$D$20 -> 615.28846 | ... Z19: =(Z7+Z9)*Assumptions!$D$20 -> 1168.2692 | AA19: =SUM(C19:N19) -> 6139.9038 | AB19: =SUM(O19:Z19) -> 13375.385 | AC19: =AA19+AB19 -> 19515.288
A20: Total costs | C20: =SUM(C17:C19) -> 6673.0769 | D20: =SUM(D17:D19) -> 8225 | E20: =SUM(E17:E19) -> 9776.9231 | F20: =SUM(F17:F19) -> 11328.846 | G20: =SUM(G17:G19) -> 12880.769 | H20: =SUM(H17:H19) -> 14432.692 | I20: =SUM(I17:I19) -> 16045.192 | J20: =SUM(J17:J19) -> 17615.288 | ... Z20: =SUM(Z17:Z19) -> 27668.269 | AA20: =SUM(C20:N20) -> 183139.9 | AB20: =SUM(O20:Z20) -> 328875.38 | AC20: =AA20+AB20 -> 512015.29
A21: Net profit before tax | C21: =C15-C20 -> 2288.4615 | D21: =D15-D20 -> 3425 | E21: =E15-E20 -> 4561.5385 | F21: =F15-F20 -> 5698.0769 | G21: =G15-G20 -> 6834.6154 | H21: =H15-H20 -> 7971.1538 | I21: =I15-I20 -> 10325.962 | J21: =J15-J20 -> 11827.981 | ... Z21: =Z15-Z20 -> 23533.654 | AA21: =SUM(C21:N21) -> 115264.9 | AB21: =SUM(O21:Z21) -> 269301.54 | AC21: =AA21+AB21 -> 384566.44
A22: Cumulative net profit | C22: =C21 -> 2288.4615 | D22: =C22+D21 -> 5713.4615 | E22: =D22+E21 -> 10275 | F22: =E22+F21 -> 15973.077 | G22: =F22+G21 -> 22807.692 | H22: =G22+H21 -> 30778.846 | I22: =H22+I21 -> 41104.808 | J22: =I22+J21 -> 52932.788 | K22: =J22+K21 -> 66262.788 | ... Z22: =Y22+Z21 -> 384566.44 | AA22: =N22 -> 115264.9 | AB22: =Z22 -> 384566.44 | AC22: =Z22 -> 384566.44
A23: Metrics
A24: Ad spend per new funded deal | C24: =IFERROR(C5/C7,0) -> 2600 | D24: =IFERROR(D5/D7,0) -> 2600 | E24: =IFERROR(E5/E7,0) -> 2600 | F24: =IFERROR(F5/F7,0) -> 2600 | G24: =IFERROR(G5/G7,0) -> 2600 | H24: =IFERROR(H5/H7,0) -> 2600 | I24: =IFERROR(I5/I7,0) -> 2600 | J24: =IFERROR(J5/J7,0) -> 2600 | ... AC24: =IFERROR(AC5/AC7,0) -> 2600
A25: Revenue per funded deal | C25: =IFERROR(C15/(C7+C9),0) -> 4660 | D25: =IFERROR(D15/(D7+D9),0) -> 4660 | E25: =IFERROR(E15/(E7+E9),0) -> 4660 | F25: =IFERROR(F15/(F7+F9),0) -> 4660 | G25: =IFERROR(G15/(G7+G9),0) -> 4660 | H25: =IFERROR(H15/(H7+H9),0) -> 4660 | I25: =IFERROR(I15/(I7+I9),0) -> 4353.3333 | J25: =IFERROR(J15/(J7+J9),0) -> 4306.7511 | ... AC25: =IFERROR(AC15/(AC7+AC9),0) -> 4134.8277
A26: Leads to call per business day | C26: =C6/21.7 -> 1.7724211 | D26: =D6/21.7 -> 2.3041475 | E26: =E6/21.7 -> 2.8358738 | F26: =F6/21.7 -> 3.3676001 | G26: =G6/21.7 -> 3.8993265 | H26: =H6/21.7 -> 4.4310528 | I26: =I6/21.7 -> 4.9627792 | J26: =J6/21.7 -> 5.4945055 | ... Z26: =Z6/21.7 -> 8.8621056

Sheet Strong
A1: Strong scenario: monthly projection (CAD)
A2: All inputs come from column E of the Assumptions tab (green = linked). Profit is before income tax and before paying yourself.
A4: Month | C4: 1 | D4: =C4+1 -> 2 | E4: =D4+1 -> 3 | F4: =E4+1 -> 4 | G4: =F4+1 -> 5 | H4: =G4+1 -> 6 | I4: =H4+1 -> 7 | J4: =I4+1 -> 8 | K4: =J4+1 -> 9 | ... Z4: =Y4+1 -> 24 | AA4: Year 1 | AB4: Year 2 | AC4: 24 months
A5: Ad spend | C5: =MIN(Assumptions!$E$8+(C$4-1)*Assumptions!$E$9,Assumptions!$E$10) -> 8000 | D5: =MIN(Assumptions!$E$8+(D$4-1)*Assumptions!$E$9,Assumptions!$E$10) -> 10500 | E5: =MIN(Assumptions!$E$8+(E$4-1)*Assumptions!$E$9,Assumptions!$E$10) -> 13000 | F5: =MIN(Assumptions!$E$8+(F$4-1)*Assumptions!$E$9,Assumptions!$E$10) -> 15500 | G5: =MIN(Assumptions!$E$8+(G$4-1)*Assumptions!$E$9,Assumptions!$E$10) -> 18000 | H5: =MIN(Assumptions!$E$8+(H$4-1)*Assumptions!$E$9,Assumptions!$E$10) -> 20500 | I5: =MIN(Assumptions!$E$8+(I$4-1)*Assumptions!$E$9,Assumptions!$E$10) -> 23000 | J5: =MIN(Assumptions!$E$8+(J$4-1)*Assumptions!$E$9,Assumptions!$E$10) -> 25500 | ... Z5: =MIN(Assumptions!$E$8+(Z$4-1)*Assumptions!$E$9,Assumptions!$E$10) -> 40000 | AA5: =SUM(C5:N5) -> 261000 | AB5: =SUM(O5:Z5) -> 478000 | AC5: =AA5+AB5 -> 739000
A6: Leads | C6: =C5/Assumptions!$E$6 -> 88.888889 | D6: =D5/Assumptions!$E$6 -> 116.66667 | E6: =E5/Assumptions!$E$6 -> 144.44444 | F6: =F5/Assumptions!$E$6 -> 172.22222 | G6: =G5/Assumptions!$E$6 -> 200 | H6: =H5/Assumptions!$E$6 -> 227.77778 | I6: =I5/Assumptions!$E$6 -> 255.55556 | J6: =J5/Assumptions!$E$6 -> 283.33333 | ... Z6: =Z5/Assumptions!$E$6 -> 444.44444 | AA6: =SUM(C6:N6) -> 2900 | AB6: =SUM(O6:Z6) -> 5311.1111 | AC6: =AA6+AB6 -> 8211.1111
A7: New funded deals | C7: =C6*Assumptions!$E$7 -> 6.2222222 | D7: =D6*Assumptions!$E$7 -> 8.1666667 | E7: =E6*Assumptions!$E$7 -> 10.111111 | F7: =F6*Assumptions!$E$7 -> 12.055556 | G7: =G6*Assumptions!$E$7 -> 14 | H7: =H6*Assumptions!$E$7 -> 15.944444 | I7: =I6*Assumptions!$E$7 -> 17.888889 | J7: =J6*Assumptions!$E$7 -> 19.833333 | ... Z7: =Z6*Assumptions!$E$7 -> 31.111111 | AA7: =SUM(C7:N7) -> 203 | AB7: =SUM(O7:Z7) -> 371.77778 | AC7: =AA7+AB7 -> 574.77778
A8: New funded volume | C8: =C7*Assumptions!$E$5 -> 404444.44 | D8: =D7*Assumptions!$E$5 -> 530833.33 | E8: =E7*Assumptions!$E$5 -> 657222.22 | F8: =F7*Assumptions!$E$5 -> 783611.11 | G8: =G7*Assumptions!$E$5 -> 910000 | H8: =H7*Assumptions!$E$5 -> 1036388.9 | I8: =I7*Assumptions!$E$5 -> 1162777.8 | J8: =J7*Assumptions!$E$5 -> 1289166.7 | ... Z8: =Z7*Assumptions!$E$5 -> 2022222.2 | AA8: =SUM(C8:N8) -> 13195000 | AB8: =SUM(O8:Z8) -> 24165556 | AC8: =AA8+AB8 -> 37360556
A9: Renewal deals | C9: =IF(C$4>Assumptions!$E$17,INDEX($C$7:$Z$7,C$4-Assumptions!$E$17)*Assumptions!$E$16,0) -> 0 | D9: =IF(D$4>Assumptions!$E$17,INDEX($C$7:$Z$7,D$4-Assumptions!$E$17)*Assumptions!$E$16,0) -> 0 | E9: =IF(E$4>Assumptions!$E$17,INDEX($C$7:$Z$7,E$4-Assumptions!$E$17)*Assumptions!$E$16,0) -> 0 | F9: =IF(F$4>Assumptions!$E$17,INDEX($C$7:$Z$7,F$4-Assumptions!$E$17)*Assumptions!$E$16,0) -> 0 | G9: =IF(G$4>Assumptions!$E$17,INDEX($C$7:$Z$7,G$4-Assumptions!$E$17)*Assumptions!$E$16,0) -> 0 | H9: =IF(H$4>Assumptions!$E$17,INDEX($C$7:$Z$7,H$4-Assumptions!$E$17)*Assumptions!$E$16,0) -> 2.8 | I9: =IF(I$4>Assumptions!$E$17,INDEX($C$7:$Z$7,I$4-Assumptions!$E$17)*Assumptions!$E$16,0) -> 3.675 | J9: =IF(J$4>Assumptions!$E$17,INDEX($C$7:$Z$7,J$4-Assumptions!$E$17)*Assumptions!$E$16,0) -> 4.55 | ... Z9: =IF(Z$4>Assumptions!$E$17,INDEX($C$7:$Z$7,Z$4-Assumptions!$E$17)*Assumptions!$E$16,0) -> 14 | AA9: =SUM(C9:N9) -> 37.975 | AB9: =SUM(O9:Z9) -> 150.675 | AC9: =AA9+AB9 -> 188.65
A10: Renewal volume | C10: =C9*Assumptions!$E$5 -> 0 | D10: =D9*Assumptions!$E$5 -> 0 | E10: =E9*Assumptions!$E$5 -> 0 | F10: =F9*Assumptions!$E$5 -> 0 | G10: =G9*Assumptions!$E$5 -> 0 | H10: =H9*Assumptions!$E$5 -> 182000 | I10: =I9*Assumptions!$E$5 -> 238875 | J10: =J9*Assumptions!$E$5 -> 295750 | ... Z10: =Z9*Assumptions!$E$5 -> 910000 | AA10: =SUM(C10:N10) -> 2468375 | AB10: =SUM(O10:Z10) -> 9793875 | AC10: =AA10+AB10 -> 12262250
A11: Total funded volume | C11: =C8+C10 -> 404444.44 | D11: =D8+D10 -> 530833.33 | E11: =E8+E10 -> 657222.22 | F11: =F8+F10 -> 783611.11 | G11: =G8+G10 -> 910000 | H11: =H8+H10 -> 1218388.9 | I11: =I8+I10 -> 1401652.8 | J11: =J8+J10 -> 1584916.7 | ... Z11: =Z8+Z10 -> 2932222.2 | AA11: =SUM(C11:N11) -> 15663375 | AB11: =SUM(O11:Z11) -> 33959431 | AC11: =AA11+AB11 -> 49622806
A12: Revenue
A13: Client success fees (collected) | C13: =(C8+C10*Assumptions!$E$18)*Assumptions!$E$11*Assumptions!$E$12 -> 23538.667 | D13: =(D8+D10*Assumptions!$E$18)*Assumptions!$E$11*Assumptions!$E$12 -> 30894.5 | E13: =(E8+E10*Assumptions!$E$18)*Assumptions!$E$11*Assumptions!$E$12 -> 38250.333 | F13: =(F8+F10*Assumptions!$E$18)*Assumptions!$E$11*Assumptions!$E$12 -> 45606.167 | G13: =(G8+G10*Assumptions!$E$18)*Assumptions!$E$11*Assumptions!$E$12 -> 52962 | H13: =(H8+H10*Assumptions!$E$18)*Assumptions!$E$11*Assumptions!$E$12 -> 70910.233 | I13: =(I8+I10*Assumptions!$E$18)*Assumptions!$E$11*Assumptions!$E$12 -> 81576.192 | J13: =(J8+J10*Assumptions!$E$18)*Assumptions!$E$11*Assumptions!$E$12 -> 92242.15 | ... Z13: =(Z8+Z10*Assumptions!$E$18)*Assumptions!$E$11*Assumptions!$E$12 -> 170655.33 | AA13: =SUM(C13:N13) -> 911608.43 | AB13: =SUM(O13:Z13) -> 1976438.9 | AC13: =AA13+AB13 -> 2888047.3
A14: Your 50% of AFN commission | C14: =C11*Assumptions!$E$13*Assumptions!$E$14*(1-Assumptions!$E$15) -> 19615.556 | D14: =D11*Assumptions!$E$13*Assumptions!$E$14*(1-Assumptions!$E$15) -> 25745.417 | E14: =E11*Assumptions!$E$13*Assumptions!$E$14*(1-Assumptions!$E$15) -> 31875.278 | F14: =F11*Assumptions!$E$13*Assumptions!$E$14*(1-Assumptions!$E$15) -> 38005.139 | G14: =G11*Assumptions!$E$13*Assumptions!$E$14*(1-Assumptions!$E$15) -> 44135 | H14: =H11*Assumptions!$E$13*Assumptions!$E$14*(1-Assumptions!$E$15) -> 59091.861 | I14: =I11*Assumptions!$E$13*Assumptions!$E$14*(1-Assumptions!$E$15) -> 67980.16 | J14: =J11*Assumptions!$E$13*Assumptions!$E$14*(1-Assumptions!$E$15) -> 76868.458 | ... Z14: =Z11*Assumptions!$E$13*Assumptions!$E$14*(1-Assumptions!$E$15) -> 142212.78 | AA14: =SUM(C14:N14) -> 759673.69 | AB14: =SUM(O14:Z14) -> 1647032.4 | AC14: =AA14+AB14 -> 2406706.1
A15: Total revenue | C15: =C13+C14 -> 43154.222 | D15: =D13+D14 -> 56639.917 | E15: =E13+E14 -> 70125.611 | F15: =F13+F14 -> 83611.306 | G15: =G13+G14 -> 97097 | H15: =H13+H14 -> 130002.09 | I15: =I13+I14 -> 149556.35 | J15: =J13+J14 -> 169110.61 | ... Z15: =Z13+Z14 -> 312868.11 | AA15: =SUM(C15:N15) -> 1671282.1 | AB15: =SUM(O15:Z15) -> 3623471.2 | AC15: =AA15+AB15 -> 5294753.4
A16: Costs
A17: Ad spend | C17: =C5 -> 8000 | D17: =D5 -> 10500 | E17: =E5 -> 13000 | F17: =F5 -> 15500 | G17: =G5 -> 18000 | H17: =H5 -> 20500 | I17: =I5 -> 23000 | J17: =J5 -> 25500 | ... Z17: =Z5 -> 40000 | AA17: =SUM(C17:N17) -> 261000 | AB17: =SUM(O17:Z17) -> 478000 | AC17: =AA17+AB17 -> 739000
A18: Fixed costs | C18: =Assumptions!$E$19 -> 2000 | D18: =Assumptions!$E$19 -> 2000 | E18: =Assumptions!$E$19 -> 2000 | F18: =Assumptions!$E$19 -> 2000 | G18: =Assumptions!$E$19 -> 2000 | H18: =Assumptions!$E$19 -> 2000 | I18: =Assumptions!$E$19 -> 2000 | J18: =Assumptions!$E$19 -> 2000 | ... Z18: =Assumptions!$E$19 -> 2000 | AA18: =SUM(C18:N18) -> 24000 | AB18: =SUM(O18:Z18) -> 24000 | AC18: =AA18+AB18 -> 48000
A19: Variable costs | C19: =(C7+C9)*Assumptions!$E$20 -> 560 | D19: =(D7+D9)*Assumptions!$E$20 -> 735 | E19: =(E7+E9)*Assumptions!$E$20 -> 910 | F19: =(F7+F9)*Assumptions!$E$20 -> 1085 | G19: =(G7+G9)*Assumptions!$E$20 -> 1260 | H19: =(H7+H9)*Assumptions!$E$20 -> 1687 | I19: =(I7+I9)*Assumptions!$E$20 -> 1940.75 | J19: =(J7+J9)*Assumptions!$E$20 -> 2194.5 | ... Z19: =(Z7+Z9)*Assumptions!$E$20 -> 4060 | AA19: =SUM(C19:N19) -> 21687.75 | AB19: =SUM(O19:Z19) -> 47020.75 | AC19: =AA19+AB19 -> 68708.5
A20: Total costs | C20: =SUM(C17:C19) -> 10560 | D20: =SUM(D17:D19) -> 13235 | E20: =SUM(E17:E19) -> 15910 | F20: =SUM(F17:F19) -> 18585 | G20: =SUM(G17:G19) -> 21260 | H20: =SUM(H17:H19) -> 24187 | I20: =SUM(I17:I19) -> 26940.75 | J20: =SUM(J17:J19) -> 29694.5 | ... Z20: =SUM(Z17:Z19) -> 46060 | AA20: =SUM(C20:N20) -> 306687.75 | AB20: =SUM(O20:Z20) -> 549020.75 | AC20: =AA20+AB20 -> 855708.5
A21: Net profit before tax | C21: =C15-C20 -> 32594.222 | D21: =D15-D20 -> 43404.917 | E21: =E15-E20 -> 54215.611 | F21: =F15-F20 -> 65026.306 | G21: =G15-G20 -> 75837 | H21: =H15-H20 -> 105815.09 | I21: =I15-I20 -> 122615.6 | J21: =J15-J20 -> 139416.11 | ... Z21: =Z15-Z20 -> 266808.11 | AA21: =SUM(C21:N21) -> 1364594.4 | AB21: =SUM(O21:Z21) -> 3074450.5 | AC21: =AA21+AB21 -> 4439044.9
A22: Cumulative net profit | C22: =C21 -> 32594.222 | D22: =C22+D21 -> 75999.139 | E22: =D22+E21 -> 130214.75 | F22: =E22+F21 -> 195241.06 | G22: =F22+G21 -> 271078.06 | H22: =G22+H21 -> 376893.15 | I22: =H22+I21 -> 499508.75 | J22: =I22+J21 -> 638924.86 | K22: =J22+K21 -> 795141.47 | ... Z22: =Y22+Z21 -> 4439044.9 | AA22: =N22 -> 1364594.4 | AB22: =Z22 -> 4439044.9 | AC22: =Z22 -> 4439044.9
A23: Metrics
A24: Ad spend per new funded deal | C24: =IFERROR(C5/C7,0) -> 1285.7143 | D24: =IFERROR(D5/D7,0) -> 1285.7143 | E24: =IFERROR(E5/E7,0) -> 1285.7143 | F24: =IFERROR(F5/F7,0) -> 1285.7143 | G24: =IFERROR(G5/G7,0) -> 1285.7143 | H24: =IFERROR(H5/H7,0) -> 1285.7143 | I24: =IFERROR(I5/I7,0) -> 1285.7143 | J24: =IFERROR(J5/J7,0) -> 1285.7143 | ... AC24: =IFERROR(AC5/AC7,0) -> 1285.7143
A25: Revenue per funded deal | C25: =IFERROR(C15/(C7+C9),0) -> 6935.5 | D25: =IFERROR(D15/(D7+D9),0) -> 6935.5 | E25: =IFERROR(E15/(E7+E9),0) -> 6935.5 | F25: =IFERROR(F15/(F7+F9),0) -> 6935.5 | G25: =IFERROR(G15/(G7+G9),0) -> 6935.5 | H25: =IFERROR(H15/(H7+H9),0) -> 6935.5 | I25: =IFERROR(I15/(I7+I9),0) -> 6935.5 | J25: =IFERROR(J15/(J7+J9),0) -> 6935.5 | ... AC25: =IFERROR(AC15/(AC7+AC9),0) -> 6935.5
A26: Leads to call per business day | C26: =C6/21.7 -> 4.0962622 | D26: =D6/21.7 -> 5.3763441 | E26: =E6/21.7 -> 6.656426 | F26: =F6/21.7 -> 7.9365079 | G26: =G6/21.7 -> 9.2165899 | H26: =H6/21.7 -> 10.496672 | I26: =I6/21.7 -> 11.776754 | J26: =J6/21.7 -> 13.056836 | ... Z26: =Z6/21.7 -> 20.481311

Sheet Benchmark_PrimedLoans
A1: Benchmark: Primed Loans (Laval, QC), estimate from public, self-reported figures
A2: Primed Loans' own website was not reachable from this environment; figures come from search-result summaries of the pages below (retrieved 2026-10-01). Marketing claims are unaudited. Revenue/income is an ESTIMATE, not a fact.
A4: Item | B4: Value | C4: Source / note
A5: Funds facilitated in 2023 (claimed) | B5: 140000000 | C5: Source: loanscanada.ca/lender/primed-loans (company profile, search summary)
A6: Applications processed in 2023 (claimed) | B6: 17000 | C6: Source: loanscanada.ca/lender/primed-loans (company profile, search summary)
A7: Approval rate (claimed) | B7: 0.97 | C7: Source: loanscanada.ca/lender/primed-loans (company profile, search summary). Inconsistent with the implied funded rate below.
A8: Total funded since start (claimed) | B8: 300000000 | C8: Source: smarter.loans/lenders/primed-loans (company profile, search summary)
A9: Total funded loans since start (claimed) | B9: 1400 | C9: Source: smarter.loans/lenders/primed-loans (company profile, search summary)
A10: In business since | B10: 2018 | C10: Source: zoominfo.com/c/primed-loans/503155603 (third-party estimate, often rough)
A11: Employees (third-party estimate) | B11: 1-10 | C11: Source: zoominfo.com/c/primed-loans/503155603 (third-party estimate, often rough)
A12: Revenue (third-party estimate) | B12: < $5M | C12: Source: zoominfo.com/c/primed-loans/503155603 (third-party estimate, often rough)
A14: Implied by their own numbers
A15: Average funded amount | B15: =IFERROR(B8/B9,0) -> 214285.71 | C15: Much larger than a typical cash advance: suggests many bank/CSBFP/equipment deals in the mix.
A16: Implied funded deals in 2023 | B16: =IFERROR(B5/B15,0) -> 653.33333 | C16: 2023 volume / average deal.
A17: Implied application-to-funded rate | B17: =IFERROR(B16/B6,0) -> 0.038431373 | C17: Roughly 4%, far from the 97% 'approval rate' they advertise.
A18: Implied funded deals per month | B18: =B16/12 -> 54.444444
A20: 2023 estimate (CAD) | B20: Low | C20: Mid | D20: High
A21: Blended broker revenue as % of volume | B21: 0.02 | C21: 0.04 | D21: 0.06 | E21: Assumption: bank/CSBFP loans pay ~1-2%, cash advances ~8-15%; the mix is unknown.
A22: Gross revenue (estimate) | B22: =$B$5*B21 -> 2800000 | C22: =$B$5*C21 -> 5600000 | D22: =$B$5*D21 -> 8400000
A23: Left for the owner after ads, staff and rep commissions | B23: 0.2 | C23: 0.3 | D23: 0.4 | E23: Assumption: ~17,000 paid leads/yr is a large ad budget; reps typically keep 30-50% of what they close.
A24: Owner pre-tax income (estimate) | B24: =B22*B23 -> 560000 | C24: =C22*C23 -> 1680000 | D24: =D22*D23 -> 3360000
A26: What it would take you to match the mid estimate
A27: Your annual funded volume needed (base case unit economics) | B27: =IFERROR(C24/(Assumptions!D26/Assumptions!D5),0) -> 42639594 | C27: Mid owner income / your profit per $ funded (base case, new deals only, before fixed costs).
A28: That is, funded deals per month | B28: =IFERROR(B27/Assumptions!D5/12,0) -> 71.06599
A29: As a share of Primed Loans' implied 2023 volume | B29: =IFERROR(B27/B5,0) -> 0.30456853 | C29: Your take per dollar funded is higher (MCA + 6% fee), so you need far less volume than they do.
